Workbook

Sheet Lisez-moi
A3: CE QUE J'AI FUSIONNÉ
A4: Plan A (le nôtre) | B4: Semi-marathon 22/11, Hyrox 2×/sem, natation en volume pur jusqu'à 6 000 m, vélo en variable d'ajustement, plancher 8h, plancher 10 km par sortie, série montagne toutes les 3 semaines.
A5: Plan B (ton fichier) | B5: Objectif 10 km en 36:00–36:30, trois courses de préparation, fractionné du mercredi, Hyrox light, natation 1 → 5 km.
A6: Résultat | B6: Un seul plan de 30 semaines. Bloc semi jusqu'au 22/11, puis bascule vitesse 10 km jusqu'au 21 mars. Les deux objectifs sont menés en parallèle comme tu l'as demandé — avec les conséquences listées plus bas.
A8: CE QUE J'AI CORRIGÉ DANS TON FICHIER
A9: Les trois dates de course | B9: Ton fichier annonce « dimanche 30/11/2026 », « dimanche 16/02/2027 » et « dimanche 23/03/2027 ». Aucune des trois n'est un dimanche : ce sont un lundi, un mardi et un mardi. J'ai retenu les dimanches les plus proches : 29/11/2026, 14/02/2027 et 21/03/2027. Vérifie les dates réelles de tes dossards.
A10: Les allures d'endurance — CORRECTION | B10: Je t'avais dit que les 6:30–7:00/km de ton fichier étaient faux. J'avais tort : ils sont cohérents avec ton niveau de départ (52 min au 10 km). Ce qui manquait, c'est que les allures ne peuvent pas rester fixes sur 30 semaines quand on part de 52 min pour viser 36 min. L'onglet Allures fonctionne donc avec DEUX références, actuelle et cible, et fait glisser les zones bloc par bloc : ton endurance part à 6:27/km et finit à 4:51/km.
A11: Les cibles des trois 10 km | B11: Recalculées depuis ton point de départ réel de 52 min : 46–48 min le 29/11, 40–42 min le 14/02, 36:00–36:30 le 21/03. Ton fichier annonçait 38-39 dès la première course — treize semaines après une reprise à 52 min, ce n'est pas atteignable.
A12: Le semi du 22/11 | B12: À la référence du bloc B (10 km ≈ 47:30), le semi se court vers 5:00/km, soit 1h45 à 1h52. C'est un repère, pas un chrono.
A13: Le jour de repos | B13: Ton fichier ne contient aucun jour de repos sur 26 semaines. Le dimanche reste vide dans ce plan, sauf les quatre jours de course.
A15: CE QUE TES CONTRAINTES COÛTENT
A16: Douze mois d'arrêt | B16: C'est l'information qui change tout, et elle contredit tout ce qu'on avait bâti avant. Le réamorçage passe de 3 à 6 semaines, la première séance de qualité n'arrive qu'en semaine 7, et il n'y a que deux sorties de course par semaine jusqu'à la semaine 7.
A17: Le 25 km du 29 août | B17: Remplacé par le 16 km de la même course, même jour, même lieu. Après douze mois d'arrêt, 25 km en montagne te coûteraient trois semaines de reprise pour zéro bénéfice. Si tu maintiens le 25 km, sache que c'est un choix contre le plan.
A18: La sortie montagne du 19/09 | B18: 30 km à la troisième semaine, soit plus du double de ta plus longue sortie à ce jour. C'est le point le plus fragile du plan. Si tu devais couper une chose, c'est celle-là.
A19: La sortie montagne du 12/12 | B19: 41 km en pleine préparation de vitesse 10 km. Deux entraînements qui s'annulent. Elle est dans le plan parce que tu l'as demandée, pas parce qu'elle sert l'objectif de mars.
A20: Le plancher de 8h | B20: Tenu partout sauf les quatre semaines de course (S12, S13, S24, S29). Le volume manquant part au vélo en zone 2 : aucun impact au sol, donc aucun coût tendineux.
A21: Le plancher de 10 km par sortie | B21: Tenu. Conséquence : on progresse par le nombre de sorties, pas par leur longueur — deux sorties jusqu'en semaine 6, trois ensuite.
A22: 36:00 en mars | B22: 52 min fin août, 36:00 le 21 mars : seize minutes en trente semaines, pour un athlète qui avait 34 min avant la coupure. C'est une reconstruction, pas une progression — et c'est précisément ce qui la rend plausible. Deux juges de paix : le test de 30' en semaine 5, et la course du 14/02. Sous 40 min en février, 36:30 tient.
A24: LES QUATRE COURSES
A25: Dimanche 22/11/2026 | B25: Semi-marathon — cible 1h45 à 1h52, course d'allure et repère
A26: Dimanche 29/11/2026 | B26: 10 km n°1 — cible 46 à 48 min, reconnaissance
A27: Dimanche 14/02/2027 | B27: 10 km n°2 — cible 40 à 42 min, course qui fixe l'objectif final
A28: Dimanche 21/03/2027 | B28: 10 km n°3 — OBJECTIF, cible 36:00 à 36:30
A30: COMMENT UTILISER CE FICHIER
A31: Plan détaillé | B31: Une ligne par séance. Colonnes jaunes à remplir : Fait, RPE ressenti, Notes.
A32: Synthèse hebdo | B32: Se recalcule seule : volume par discipline, kilométrage, mètres nagés, charge planifiée vs réelle.
A33: Allures | B33: Deux références : ton allure 10 km actuelle (52 min) et ta cible (36 min). Les huit zones glissent bloc par bloc, et la colonne « Allures cibles » du Plan détaillé suit automatiquement.
A34: Courses montagne | B34: Les cinq sorties longues en montagne et les courses correspondantes autour de Wrocław.
A35: Exercices Hyrox | B35: Chaque station expliquée : standard officiel, technique, erreur classique.
A37: ÉCHELLE RPE
A38: 1-2 | B38: Très facile — récupération, nage souple
A39: 3-4 | B39: Facile — endurance fondamentale
A40: 5-6 | B40: Modéré — endurance active
A41: 7 | B41: Difficile — seuil
A42: 8 | B42: Très difficile — allure 10 km, VMA
A43: 9 | B43: Quasi maximal — test, 400 m
A44: 10 | B44: Maximal — course
A45: Charge | B45: Charge = durée (min) × RPE. À lire en relatif d'une semaine à l'autre.

Sheet Plan détaillé
A1: Semaine | B1: Phase | C1: Date | D1: Jour | E1: Discipline | F1: Séance | G1: Durée (min) | H1: Course (km) | I1: Natation (m) | J1: Zones d'allure | K1: Allures cibles (min/km) | L1: RPE cible | M1: Charge planifiée | N1: Détail de la séance | O1: Fait (x) | P1: RPE ressenti | Q1: Charge réelle | R1: Notes
A2: 0 | B2: Avant le plan | C2: 46263 | D2: Samedi | E2: Course à pied | F2: CAP · MONTAGNE — 16 km · course | G2: 140 | H2: 16 | J2: Montagne | K2: ="À l'effort, pas à l'allure — marche en côte assumée" -> À l'effort, pas à l'allure — marche en côte assumée | L2: 6 | M2: =G2*L2 -> 840 | N2: <b>Course : Bieg Jaskiniowego Niedźwiedzia</b> — Kletno, Masyw Śnieżnika, samedi 29/08/2026. Sortie d'ouverture, deux jours avant le début du plan. Après douze mois d'arrêt, prends le 16 km, pas le 25 : marche dès que la pente dépasse 8 %, ravitaillement toutes les 45 minutes, et de quoi rentrer si ça tourne mal. Dimanche et lundi sont des jours de repos réels. | Q2: =IF(P2="","",G2*P2)
A3: 0 | B3: Avant le plan | C3: 46264 | D3: Dimanche | E3: Repos | F3: Repos complet | G3: 0 | L3: 0 | M3: =G3*L3 -> 0 | N3: Repos complet obligatoire. | Q3: =IF(P3="","",G3*P3)
A4: 1 | B4: Réamorçage · coupure pro | C4: 46265 | D4: Lundi | E4: Hyrox | F4: Hyrox n°1 · Force | G4: 60 | L4: 5 | M4: =G4*L4 -> 300 | N4: Échauffement 12' (rameur souple, mobilité hanches et chevilles). Air squat 3 × 15, goblet squat 3 × 12 léger, hip thrust 3 × 12, tirage horizontal 3 × 12. Ski erg 4 × 250 m. Farmer's carry 3 × 30 m. Gainage 12'. <b>Aucun sled.</b> Deux jours après les 16 km de montagne : si les jambes sont marquées, tu enlèves 30 % de charge sans discuter. C'est ta dernière séance en salle avant quatre jours d'arrêt. | Q4: =IF(P4="","",G4*P4)
A5: 1 | B5: Réamorçage · coupure pro | C5: 46266 | D5: Mardi (matin) | E5: Natation | F5: Natation · Volume — séries longues | G5: 60 | I5: 2400 | L5: 5 | M5: =G5*L5 -> 300 | N5: 400 · 5 × 300 (r 20") · 3 × 100 · 200. ≈ 2 400 m. Légèrement allongée par rapport au plan initial : c'est ta dernière séance en bassin avant la coupure. | Q5: =IF(P5="","",G5*P5)
A6: 1 | B6: Réamorçage · coupure pro | C6: 46266 | D6: Mardi (soir) | E6: Vélo | F6: Vélo · Endurance longue | G6: 90 | L6: 4 | M6: =G6*L6 -> 360 | N6: 1h30 en zone 2, cadence 85 à 95, aucune bosse en force. Allongée de 25 minutes : c'est le dernier volume aérobie de la semaine. Home trainer ou route, peu importe. | Q6: =IF(P6="","",G6*P6)
A7: 1 | B7: Réamorçage · coupure pro | C7: 46267 | D7: Mercredi | E7: Repos | F7: Déplacement professionnel — aucun entraînement | G7: 0 | L7: 0 | M7: =G7*L7 -> 0 | N7: <b>Coupure imposée du 2 au 5 septembre.</b> Rien à faire, rien à compenser. Ce qui compte ces quatre jours : dormir correctement malgré les horaires, boire, et marcher dès que tu peux au lieu de prendre un taxi. Aucune séance de rattrapage au retour. | Q7: =IF(P7="","",G7*P7)
A8: 1 | B8: Réamorçage · coupure pro | C8: 46268 | D8: Jeudi | E8: Repos | F8: Déplacement professionnel — aucun entraînement | G8: 0 | L8: 0 | M8: =G8*L8 -> 0 | N8: Jour 2 sur 4. | Q8: =IF(P8="","",G8*P8)
A9: 1 | B9: Réamorçage · coupure pro | C9: 46269 | D9: Vendredi | E9: Repos | F9: Déplacement professionnel — aucun entraînement | G9: 0 | L9: 0 | M9: =G9*L9 -> 0 | N9: Jour 3 sur 4. | Q9: =IF(P9="","",G9*P9)
A10: 1 | B10: Réamorçage · coupure pro | C10: 46270 | D10: Samedi | E10: Repos | F10: Déplacement professionnel — aucun entraînement | G10: 0 | L10: 0 | M10: =G10*L10 -> 0 | N10: Jour 4 sur 4. La sortie longue de la semaine est annulée, pas décalée : on ne rattrape pas 12 km au retour d'un déplacement, on reprend là où le plan en est. | Q10: =IF(P10="","",G10*P10)
A11: 1 | B11: Réamorçage · coupure pro | C11: 46271 | D11: Dimanche | E11: Course à pied | F11: CAP · Footing de reprise | G11: 65 | H11: 10 | J11: EF | K11: ="EF "&TEXT((Allures!$C$13+75)/86400,"mm:ss") -> EF 06:27 | L11: 3 | M11: =G11*L11 -> 195 | N11: 65' en endurance fondamentale, 10 km, allure unique. <b>Le dimanche devient un jour d'entraînement cette semaine-là</b> — après quatre jours de coupure, tu n'as pas besoin du jour de repos habituel. Séance de remise en route pure : aucune allure imposée, aucune ligne droite, rien. | Q11: =IF(P11="","",G11*P11)
A12: 2 | B12: Réamorçage long | C12: 46272 | D12: Lundi | E12: Hyrox | F12: Hyrox n°1 · Force | G12: 70 | L12: 5 | M12: =G12*L12 -> 350 | N12: Échauffement 12' (rameur souple, mobilité hanches et chevilles). Squat 3 × 12 léger, soulevé de terre roumain 3 × 10, hip thrust 3 × 12. <b>Aucun sled : après douze mois d'arrêt, on apprend les positions avant de charger.</b> Ski erg 4 × 250 m. Farmer's carry 3 × 30 m. Gainage 12'. | Q12: =IF(P12="","",G12*P12)
A13: 2 | B13: Réamorçage long | C13: 46273 | D13: Mardi (matin) | E13: Natation | F13: Natation · Volume — séries longues | G13: 55 | I13: 2400 | L13: 5 | M13: =G13*L13 -> 275 | N13: 400 · 5 × 300 (r 20") · 3 × 100 · 200. ≈ 2 400 m. Nage continue, aucune technique isolée : séance de volume. | Q13: =IF(P13="","",G13*P13)
A14: 2 | B14: Réamorçage long | C14: 46273 | D14: Mardi (soir) | E14: Vélo | F14: Vélo · Endurance | G14: 70 | L14: 4 | M14: =G14*L14 -> 280 | N14: Endurance stricte en zone 2 : allure conversation, cadence 85 à 95, aucune bosse en force. Home trainer ou route — c'est du volume aérobie sans impact, rien d'autre. | Q14: =IF(P14="","",G14*P14)
A15: 2 | B15: Réamorçage long | C15: 46274 | D15: Mercredi | E15: Course à pied | F15: CAP · Footing d'endurance | G15: 58 | H15: 10 | J15: EF | K15: ="EF "&TEXT((Allures!$C$13+75)/86400,"mm:ss") -> EF 06:27 | L15: 3 | M15: =G15*L15 -> 174 | N15: 58' en endurance fondamentale, allure unique, terrain plat. 10 km. 6 × 20" de lignes droites relâchées en fin de séance. | Q15: =IF(P15="","",G15*P15)
A16: 2 | B16: Réamorçage long | C16: 46275 | D16: Jeudi | E16: Hyrox | F16: Hyrox n°2 · Circuit aérobie | G16: 60 | H16: 1.2 | L16: 5 | M16: =G16*L16 -> 300 | N16: 3 tours à allure conversation : 500 m rameur · 15 wall balls · 400 m course · 10 burpees · 30 m farmers. Récupération 2'. | Q16: =IF(P16="","",G16*P16)
A17: 2 | B17: Réamorçage long | C17: 46276 | D17: Vendredi (matin) | E17: Natation | F17: Natation · Volume — densité | G17: 40 | I17: 1800 | L17: 4 | M17: =G17*L17 -> 160 | N17: 300 · 12 × 100 (r 15") · 6 × 50. ≈ 1 800 m. Récupérations courtes, allure constante. | Q17: =IF(P17="","",G17*P17)
A18: 2 | B18: Réamorçage long | C18: 46276 | D18: Vendredi (soir) | E18: Vélo | F18: Vélo · Déverrouillage | G18: 52 | L18: 3 | M18: =G18*L18 -> 156 | N18: Déverrouillage en zone 1-2, home trainer suffisant. Cadence haute, faible couple. Si tu as des watts en tête, tu t'es trompé de séance. | Q18: =IF(P18="","",G18*P18)
A19: 2 | B19: Réamorçage long | C19: 46277 | D19: Samedi | E19: Course à pied | F19: CAP · Sortie longue | G19: 75 | H19: 13 | J19: EF | K19: ="EF "&TEXT((Allures!$C$13+75)/86400,"mm:ss") -> EF 06:27 | L19: 3 | M19: =G19*L19 -> 225 | N19: 75' en endurance fondamentale, allure unique, terrain plat. 13 km. Aucune allure imposée : après douze mois d'arrêt, la sortie longue construit du tendon, pas du cardio. | Q19: =IF(P19="","",G19*P19)
A20: 2 | B20: Réamorçage long | C20: 46278 | D20: Dimanche | E20: Repos | F20: Repos complet | G20: 0 | L20: 0 | M20: =G20*L20 -> 0 | N20: Repos complet. Option : 20' de mobilité. | Q20: =IF(P20="","",G20*P20)
A21: 3 | B21: Réamorçage long | C21: 46279 | D21: Lundi | E21: Hyrox | F21: Hyrox n°1 · Force | G21: 80 | L21: 6 | M21: =G21*L21 -> 480 | N21: Échauffement 12' (rameur souple, mobilité hanches et chevilles). Squat 4 × 8, soulevé de terre roumain 3 × 10, fentes bulgares 3 × 10 par jambe. Sled push 4 × 15 m à vide ou très léger, technique seulement. Ski erg 5 × 250 m. Farmer's carry 4 × 40 m. Gainage 12'. | Q21: =IF(P21="","",G21*P21)
A22: 3 | B22: Réamorçage long | C22: 46280 | D22: Mardi | E22: Natation | F22: Natation · Volume — séries longues | G22: 60 | I22: 2600 | L22: 5 | M22: =G22*L22 -> 300 | N22: 400 · 4 × 400 (r 25") · 4 × 100 · 200. ≈ 2 600 m. Nage continue, aucune technique isolée : séance de volume. | Q22: =IF(P22="","",G22*P22)
A23: 3 | B23: Réamorçage long | C23: 46281 | D23: Mercredi | E23: Course à pied | F23: CAP · Footing d'endurance | G23: 63 | H23: 11 | J23: EF | K23: ="EF "&TEXT((Allures!$C$13+75)/86400,"mm:ss") -> EF 06:27 | L23: 3 | M23: =G23*L23 -> 189 | N23: 63' en endurance fondamentale, allure unique, terrain plat. 11 km. 6 × 20" de lignes droites relâchées en fin de séance. | Q23: =IF(P23="","",G23*P23)
A24: 3 | B24: Réamorçage long | C24: 46282 | D24: Jeudi | E24: Hyrox | F24: Hyrox n°2 · Allégé (semaine montagne) | G24: 45 | H24: 1.2 | L24: 5 | M24: =G24*L24 -> 225 | N24: 3 blocs seulement : 400 m souple + 1 station. La sortie montagne est la priorité absolue de la semaine. | Q24: =IF(P24="","",G24*P24)
A25: 3 | B25: Réamorçage long | C25: 46283 | D25: Vendredi | E25: Natation | F25: Natation · Volume — densité | G25: 45 | I25: 2000 | L25: 4 | M25: =G25*L25 -> 180 | N25: 300 · 8 × 200 (r 20") · 100. ≈ 2 000 m. Récupérations courtes, allure constante. | Q25: =IF(P25="","",G25*P25)
A26: 3 | B26: Réamorçage long | C26: 46284 | D26: Samedi | E26: Course à pied | F26: CAP · MONTAGNE — 30 km · course | G26: 235 | H26: 30 | J26: Montagne | K26: ="À l'effort, pas à l'allure — marche en côte assumée" -> À l'effort, pas à l'allure — marche en côte assumée | L26: 7 | M26: =G26*L26 -> 1645 | N26: <b>Course : Przejście Nocna 30 — 30 km</b> — Départ Piechowice, arrivée Szklarska Poręba, 18–20/09/2026, course de nuit. <b>+14 km sur la précédente.</b> C'est le saut le plus violent de tout le plan et il arrive à la troisième semaine. Effort constant, marche en côte assumée, aucune notion d'allure. Objectif : finir, pas courir. | Q26: =IF(P26="","",G26*P26)
A27: 3 | B27: Réamorçage long | C27: 46285 | D27: Dimanche | E27: Repos | F27: Repos complet | G27: 0 | L27: 0 | M27: =G27*L27 -> 0 | N27: Repos complet après la montagne. | Q27: =IF(P27="","",G27*P27)
A28: 4 | B28: Réamorçage · allégée | C28: 46286 | D28: Lundi | E28: Hyrox | F28: Hyrox n°1 · Force | G28: 80 | L28: 6 | M28: =G28*L28 -> 480 | N28: Échauffement 12' (rameur souple, mobilité hanches et chevilles). Squat 4 × 8, soulevé de terre roumain 3 × 10, fentes bulgares 3 × 10 par jambe. Sled push 4 × 15 m à vide ou très léger, technique seulement. Ski erg 5 × 250 m. Farmer's carry 4 × 40 m. Gainage 12'. | Q28: =IF(P28="","",G28*P28)
A29: 4 | B29: Réamorçage · allégée | C29: 46287 | D29: Mardi (matin) | E29: Natation | F29: Natation · Volume — séries longues | G29: 65 | I29: 2800 | L29: 5 | M29: =G29*L29 -> 325 | N29: 400 · 5 × 400 (r 25") · 2 × 100 · 200. ≈ 2 800 m. Nage continue, aucune technique isolée : séance de volume. | Q29: =IF(P29="","",G29*P29)
A30: 4 | B30: Réamorçage · allégée | C30: 46287 | D30: Mardi (soir) | E30: Vélo | F30: Vélo · Endurance | G30: 82 | L30: 4 | M30: =G30*L30 -> 328 | N30: Endurance stricte en zone 2 : allure conversation, cadence 85 à 95, aucune bosse en force. Home trainer ou route — c'est du volume aérobie sans impact, rien d'autre. | Q30: =IF(P30="","",G30*P30)
A31: 4 | B31: Réamorçage · allégée | C31: 46288 | D31: Mercredi | E31: Course à pied | F31: CAP · Footing d'endurance | G31: 58 | H31: 10 | J31: EF | K31: ="EF "&TEXT((Allures!$C$13+75)/86400,"mm:ss") -> EF 06:27 | L31: 3 | M31: =G31*L31 -> 174 | N31: 58' en endurance fondamentale, allure unique, terrain plat. 10 km. 6 × 20" de lignes droites relâchées en fin de séance. | Q31: =IF(P31="","",G31*P31)
A32: 4 | B32: Réamorçage · allégée | C32: 46289 | D32: Jeudi | E32: Hyrox | F32: Hyrox n°2 · Course dégradée | G32: 75 | H32: 2 | L32: 6 | M32: =G32*L32 -> 450 | N32: 5 blocs : 400 m à allure 10 km + 1 station (ski 500 m / 20 wall balls / 40 m farmers / rameur 500 m / 20 m fentes sandbag). Récupération 90". | Q32: =IF(P32="","",G32*P32)
A33: 4 | B33: Réamorçage · allégée | C33: 46290 | D33: Vendredi | E33: Natation | F33: Natation · Volume — densité | G33: 50 | I33: 2200 | L33: 4 | M33: =G33*L33 -> 200 | N33: 300 · 9 × 200 (r 20") · 100. ≈ 2 200 m. Récupérations courtes, allure constante. | Q33: =IF(P33="","",G33*P33)
A34: 4 | B34: Réamorçage · allégée | C34: 46291 | D34: Samedi | E34: Course à pied | F34: CAP · Sortie longue | G34: 70 | H34: 12 | J34: EF | K34: ="EF "&TEXT((Allures!$C$13+75)/86400,"mm:ss") -> EF 06:27 | L34: 3 | M34: =G34*L34 -> 210 | N34: 70' en endurance fondamentale, allure unique, terrain plat. 12 km. Aucune allure imposée : après douze mois d'arrêt, la sortie longue construit du tendon, pas du cardio. | Q34: =IF(P34="","",G34*P34)
A35: 4 | B35: Réamorçage · allégée | C35: 46292 | D35: Dimanche | E35: Repos | F35: Repos complet | G35: 0 | L35: 0 | M35: =G35*L35 -> 0 | N35: Repos complet. Option : 20' de mobilité. | Q35: =IF(P35="","",G35*P35)
A36: 5 | B36: Réamorçage long | C36: 46293 | D36: Lundi | E36: Hyrox | F36: Hyrox n°1 · Force | G36: 85 | L36: 7 | M36: =G36*L36 -> 595 | N36: Échauffement 12' (rameur souple, mobilité hanches et chevilles). Squat 4 × 6, soulevé de terre roumain 4 × 8, fentes bulgares 3 × 12 par jambe. Sled push et pull 4 × 15 m, charge modérée — premières charges réelles. Ski erg 4 × 500 m. Farmer's carry 4 × 40 m. Gainage 12'. | Q36: =IF(P36="","",G36*P36)
A37: 5 | B37: Réamorçage long | C37: 46294 | D37: Mardi (matin) | E37: Natation | F37: Natation · Volume — séries longues | G37: 70 | I37: 3000 | L37: 5 | M37: =G37*L37 -> 350 | N37: 400 · 4 × 500 (r 30") · 4 × 100 · 200. ≈ 3 000 m. Nage continue, aucune technique isolée : séance de volume. | Q37: =IF(P37="","",G37*P37)
A38: 5 | B38: Réamorçage long | C38: 46294 | D38: Mardi (soir) | E38: Vélo | F38: Vélo · Déverrouillage | G38: 52 | L38: 3 | M38: =G38*L38 -> 156 | N38: Déverrouillage en zone 1-2, home trainer suffisant. Cadence haute, faible couple. Si tu as des watts en tête, tu t'es trompé de séance. | Q38: =IF(P38="","",G38*P38)
A39: 5 | B39: Réamorçage long | C39: 46295 | D39: Mercredi | E39: Course à pied | F39: CAP · TEST 30' contre-la-montre | G39: 63 | H39: 11 | J39: Test 30' | K39: ="Effort max régulier — le test donne l'allure seuil" -> Effort max régulier — le test donne l'allure seuil | L39: 9 | M39: =G39*L39 -> 567 | N39: 20' échauffement avec 4 × 30" progressifs · 30' à l'effort maximal soutenable · 10' retour au calme. 11 km. Ce test tranche tout : ton allure moyenne sur 30' est ton allure seuil, et ton allure 10 km se situe environ 10 s/km plus rapide. Reporte-la dans l'onglet Allures — les 24 semaines suivantes se recalent dessus. | Q39: =IF(P39="","",G39*P39)
A40: 5 | B40: Réamorçage long | C40: 46296 | D40: Jeudi | E40: Hyrox | F40: Hyrox n°2 · Course dégradée | G40: 75 | H40: 2 | L40: 6 | M40: =G40*L40 -> 450 | N40: 5 blocs : 400 m à allure 10 km + 1 station (ski 500 m / 20 wall balls / 40 m farmers / rameur 500 m / 20 m fentes sandbag). Récupération 90". | Q40: =IF(P40="","",G40*P40)
...

Sheet Synthèse hebdo
A1: Semaine | B1: Phase | C1: Volume total (h) | D1: Course (h) | E1: Hyrox (h) | F1: Natation (h) | G1: Vélo (h) | H1: Course (km) | I1: Natation (m) | J1: Charge planifiée | K1: Charge réelle | L1: Écart charge | M1: Séances faites | N1: RPE moyen ressenti
A2: 0 | B2: Avant le plan | C2: =SUMIFS('Plan détaillé'!$G$2:$G$244,'Plan détaillé'!$A$2:$A$244,$A2)/60 -> 2.3333333 | D2: =SUMIFS('Plan détaillé'!$G$2:$G$244,'Plan détaillé'!$A$2:$A$244,$A2,'Plan détaillé'!$E$2:$E$244,"Course à pied")/60 -> 2.3333333 | E2: =SUMIFS('Plan détaillé'!$G$2:$G$244,'Plan détaillé'!$A$2:$A$244,$A2,'Plan détaillé'!$E$2:$E$244,"Hyrox")/60 -> 0 | F2: =SUMIFS('Plan détaillé'!$G$2:$G$244,'Plan détaillé'!$A$2:$A$244,$A2,'Plan détaillé'!$E$2:$E$244,"Natation")/60 -> 0 | G2: =SUMIFS('Plan détaillé'!$G$2:$G$244,'Plan détaillé'!$A$2:$A$244,$A2,'Plan détaillé'!$E$2:$E$244,"Vélo")/60 -> 0 | H2: =SUMIFS('Plan détaillé'!$H$2:$H$244,'Plan détaillé'!$A$2:$A$244,$A2) -> 16 | I2: =SUMIFS('Plan détaillé'!$I$2:$I$244,'Plan détaillé'!$A$2:$A$244,$A2) -> 0 | J2: =SUMIFS('Plan détaillé'!$M$2:$M$244,'Plan détaillé'!$A$2:$A$244,$A2) -> 840 | K2: =SUMIFS('Plan détaillé'!$Q$2:$Q$244,'Plan détaillé'!$A$2:$A$244,$A2) -> 0 | L2: =IF(J2=0,"",IFERROR(K2/J2-1,"")) -> -1 | M2: =COUNTIFS('Plan détaillé'!$A$2:$A$244,$A2,'Plan détaillé'!$O$2:$O$244,"x") -> 0 | N2: =IFERROR(AVERAGEIFS('Plan détaillé'!$P$2:$P$244,'Plan détaillé'!$A$2:$A$244,$A2,'Plan détaillé'!$P$2:$P$244,">0"),"")
A3: 1 | B3: Réamorçage · coupure pro | C3: =SUMIFS('Plan détaillé'!$G$2:$G$244,'Plan détaillé'!$A$2:$A$244,$A3)/60 -> 4.5833333 | D3: =SUMIFS('Plan détaillé'!$G$2:$G$244,'Plan détaillé'!$A$2:$A$244,$A3,'Plan détaillé'!$E$2:$E$244,"Course à pied")/60 -> 1.0833333 | E3: =SUMIFS('Plan détaillé'!$G$2:$G$244,'Plan détaillé'!$A$2:$A$244,$A3,'Plan détaillé'!$E$2:$E$244,"Hyrox")/60 -> 1 | F3: =SUMIFS('Plan détaillé'!$G$2:$G$244,'Plan détaillé'!$A$2:$A$244,$A3,'Plan détaillé'!$E$2:$E$244,"Natation")/60 -> 1 | G3: =SUMIFS('Plan détaillé'!$G$2:$G$244,'Plan détaillé'!$A$2:$A$244,$A3,'Plan détaillé'!$E$2:$E$244,"Vélo")/60 -> 1.5 | H3: =SUMIFS('Plan détaillé'!$H$2:$H$244,'Plan détaillé'!$A$2:$A$244,$A3) -> 10 | I3: =SUMIFS('Plan détaillé'!$I$2:$I$244,'Plan détaillé'!$A$2:$A$244,$A3) -> 2400 | J3: =SUMIFS('Plan détaillé'!$M$2:$M$244,'Plan détaillé'!$A$2:$A$244,$A3) -> 1155 | K3: =SUMIFS('Plan détaillé'!$Q$2:$Q$244,'Plan détaillé'!$A$2:$A$244,$A3) -> 0 | L3: =IF(J3=0,"",IFERROR(K3/J3-1,"")) -> -1 | M3: =COUNTIFS('Plan détaillé'!$A$2:$A$244,$A3,'Plan détaillé'!$O$2:$O$244,"x") -> 0 | N3: =IFERROR(AVERAGEIFS('Plan détaillé'!$P$2:$P$244,'Plan détaillé'!$A$2:$A$244,$A3,'Plan détaillé'!$P$2:$P$244,">0"),"")
A4: 2 | B4: Réamorçage long | C4: =SUMIFS('Plan détaillé'!$G$2:$G$244,'Plan détaillé'!$A$2:$A$244,$A4)/60 -> 8 | D4: =SUMIFS('Plan détaillé'!$G$2:$G$244,'Plan détaillé'!$A$2:$A$244,$A4,'Plan détaillé'!$E$2:$E$244,"Course à pied")/60 -> 2.2166667 | E4: =SUMIFS('Plan détaillé'!$G$2:$G$244,'Plan détaillé'!$A$2:$A$244,$A4,'Plan détaillé'!$E$2:$E$244,"Hyrox")/60 -> 2.1666667 | F4: =SUMIFS('Plan détaillé'!$G$2:$G$244,'Plan détaillé'!$A$2:$A$244,$A4,'Plan détaillé'!$E$2:$E$244,"Natation")/60 -> 1.5833333 | G4: =SUMIFS('Plan détaillé'!$G$2:$G$244,'Plan détaillé'!$A$2:$A$244,$A4,'Plan détaillé'!$E$2:$E$244,"Vélo")/60 -> 2.0333333 | H4: =SUMIFS('Plan détaillé'!$H$2:$H$244,'Plan détaillé'!$A$2:$A$244,$A4) -> 24.2 | I4: =SUMIFS('Plan détaillé'!$I$2:$I$244,'Plan détaillé'!$A$2:$A$244,$A4) -> 4200 | J4: =SUMIFS('Plan détaillé'!$M$2:$M$244,'Plan détaillé'!$A$2:$A$244,$A4) -> 1920 | K4: =SUMIFS('Plan détaillé'!$Q$2:$Q$244,'Plan détaillé'!$A$2:$A$244,$A4) -> 0 | L4: =IF(J4=0,"",IFERROR(K4/J4-1,"")) -> -1 | M4: =COUNTIFS('Plan détaillé'!$A$2:$A$244,$A4,'Plan détaillé'!$O$2:$O$244,"x") -> 0 | N4: =IFERROR(AVERAGEIFS('Plan détaillé'!$P$2:$P$244,'Plan détaillé'!$A$2:$A$244,$A4,'Plan détaillé'!$P$2:$P$244,">0"),"")
A5: 3 | B5: Réamorçage long | C5: =SUMIFS('Plan détaillé'!$G$2:$G$244,'Plan détaillé'!$A$2:$A$244,$A5)/60 -> 8.8 | D5: =SUMIFS('Plan détaillé'!$G$2:$G$244,'Plan détaillé'!$A$2:$A$244,$A5,'Plan détaillé'!$E$2:$E$244,"Course à pied")/60 -> 4.9666667 | E5: =SUMIFS('Plan détaillé'!$G$2:$G$244,'Plan détaillé'!$A$2:$A$244,$A5,'Plan détaillé'!$E$2:$E$244,"Hyrox")/60 -> 2.0833333 | F5: =SUMIFS('Plan détaillé'!$G$2:$G$244,'Plan détaillé'!$A$2:$A$244,$A5,'Plan détaillé'!$E$2:$E$244,"Natation")/60 -> 1.75 | G5: =SUMIFS('Plan détaillé'!$G$2:$G$244,'Plan détaillé'!$A$2:$A$244,$A5,'Plan détaillé'!$E$2:$E$244,"Vélo")/60 -> 0 | H5: =SUMIFS('Plan détaillé'!$H$2:$H$244,'Plan détaillé'!$A$2:$A$244,$A5) -> 42.2 | I5: =SUMIFS('Plan détaillé'!$I$2:$I$244,'Plan détaillé'!$A$2:$A$244,$A5) -> 4600 | J5: =SUMIFS('Plan détaillé'!$M$2:$M$244,'Plan détaillé'!$A$2:$A$244,$A5) -> 3019 | K5: =SUMIFS('Plan détaillé'!$Q$2:$Q$244,'Plan détaillé'!$A$2:$A$244,$A5) -> 0 | L5: =IF(J5=0,"",IFERROR(K5/J5-1,"")) -> -1 | M5: =COUNTIFS('Plan détaillé'!$A$2:$A$244,$A5,'Plan détaillé'!$O$2:$O$244,"x") -> 0 | N5: =IFERROR(AVERAGEIFS('Plan détaillé'!$P$2:$P$244,'Plan détaillé'!$A$2:$A$244,$A5,'Plan détaillé'!$P$2:$P$244,">0"),"")
A6: 4 | B6: Réamorçage · allégée | C6: =SUMIFS('Plan détaillé'!$G$2:$G$244,'Plan détaillé'!$A$2:$A$244,$A6)/60 -> 8 | D6: =SUMIFS('Plan détaillé'!$G$2:$G$244,'Plan détaillé'!$A$2:$A$244,$A6,'Plan détaillé'!$E$2:$E$244,"Course à pied")/60 -> 2.1333333 | E6: =SUMIFS('Plan détaillé'!$G$2:$G$244,'Plan détaillé'!$A$2:$A$244,$A6,'Plan détaillé'!$E$2:$E$244,"Hyrox")/60 -> 2.5833333 | F6: =SUMIFS('Plan détaillé'!$G$2:$G$244,'Plan détaillé'!$A$2:$A$244,$A6,'Plan détaillé'!$E$2:$E$244,"Natation")/60 -> 1.9166667 | G6: =SUMIFS('Plan détaillé'!$G$2:$G$244,'Plan détaillé'!$A$2:$A$244,$A6,'Plan détaillé'!$E$2:$E$244,"Vélo")/60 -> 1.3666667 | H6: =SUMIFS('Plan détaillé'!$H$2:$H$244,'Plan détaillé'!$A$2:$A$244,$A6) -> 24 | I6: =SUMIFS('Plan détaillé'!$I$2:$I$244,'Plan détaillé'!$A$2:$A$244,$A6) -> 5000 | J6: =SUMIFS('Plan détaillé'!$M$2:$M$244,'Plan détaillé'!$A$2:$A$244,$A6) -> 2167 | K6: =SUMIFS('Plan détaillé'!$Q$2:$Q$244,'Plan détaillé'!$A$2:$A$244,$A6) -> 0 | L6: =IF(J6=0,"",IFERROR(K6/J6-1,"")) -> -1 | M6: =COUNTIFS('Plan détaillé'!$A$2:$A$244,$A6,'Plan détaillé'!$O$2:$O$244,"x") -> 0 | N6: =IFERROR(AVERAGEIFS('Plan détaillé'!$P$2:$P$244,'Plan détaillé'!$A$2:$A$244,$A6,'Plan détaillé'!$P$2:$P$244,">0"),"")
A7: 5 | B7: Réamorçage long | C7: =SUMIFS('Plan détaillé'!$G$2:$G$244,'Plan détaillé'!$A$2:$A$244,$A7)/60 -> 8 | D7: =SUMIFS('Plan détaillé'!$G$2:$G$244,'Plan détaillé'!$A$2:$A$244,$A7,'Plan détaillé'!$E$2:$E$244,"Course à pied")/60 -> 2.4666667 | E7: =SUMIFS('Plan détaillé'!$G$2:$G$244,'Plan détaillé'!$A$2:$A$244,$A7,'Plan détaillé'!$E$2:$E$244,"Hyrox")/60 -> 2.6666667 | F7: =SUMIFS('Plan détaillé'!$G$2:$G$244,'Plan détaillé'!$A$2:$A$244,$A7,'Plan détaillé'!$E$2:$E$244,"Natation")/60 -> 2 | G7: =SUMIFS('Plan détaillé'!$G$2:$G$244,'Plan détaillé'!$A$2:$A$244,$A7,'Plan détaillé'!$E$2:$E$244,"Vélo")/60 -> 0.86666667 | H7: =SUMIFS('Plan détaillé'!$H$2:$H$244,'Plan détaillé'!$A$2:$A$244,$A7) -> 28 | I7: =SUMIFS('Plan détaillé'!$I$2:$I$244,'Plan détaillé'!$A$2:$A$244,$A7) -> 5400 | J7: =SUMIFS('Plan détaillé'!$M$2:$M$244,'Plan détaillé'!$A$2:$A$244,$A7) -> 2573 | K7: =SUMIFS('Plan détaillé'!$Q$2:$Q$244,'Plan détaillé'!$A$2:$A$244,$A7) -> 0 | L7: =IF(J7=0,"",IFERROR(K7/J7-1,"")) -> -1 | M7: =COUNTIFS('Plan détaillé'!$A$2:$A$244,$A7,'Plan détaillé'!$O$2:$O$244,"x") -> 0 | N7: =IFERROR(AVERAGEIFS('Plan détaillé'!$P$2:$P$244,'Plan détaillé'!$A$2:$A$244,$A7,'Plan détaillé'!$P$2:$P$244,">0"),"")
A8: 6 | B8: Réamorçage long | C8: =SUMIFS('Plan détaillé'!$G$2:$G$244,'Plan détaillé'!$A$2:$A$244,$A8)/60 -> 9.8833333 | D8: =SUMIFS('Plan détaillé'!$G$2:$G$244,'Plan détaillé'!$A$2:$A$244,$A8,'Plan détaillé'!$E$2:$E$244,"Course à pied")/60 -> 5.6333333 | E8: =SUMIFS('Plan détaillé'!$G$2:$G$244,'Plan détaillé'!$A$2:$A$244,$A8,'Plan détaillé'!$E$2:$E$244,"Hyrox")/60 -> 2.1666667 | F8: =SUMIFS('Plan détaillé'!$G$2:$G$244,'Plan détaillé'!$A$2:$A$244,$A8,'Plan détaillé'!$E$2:$E$244,"Natation")/60 -> 2.0833333 | G8: =SUMIFS('Plan détaillé'!$G$2:$G$244,'Plan détaillé'!$A$2:$A$244,$A8,'Plan détaillé'!$E$2:$E$244,"Vélo")/60 -> 0 | H8: =SUMIFS('Plan détaillé'!$H$2:$H$244,'Plan détaillé'!$A$2:$A$244,$A8) -> 49 | I8: =SUMIFS('Plan détaillé'!$I$2:$I$244,'Plan détaillé'!$A$2:$A$244,$A8) -> 5800 | J8: =SUMIFS('Plan détaillé'!$M$2:$M$244,'Plan détaillé'!$A$2:$A$244,$A8) -> 3484 | K8: =SUMIFS('Plan détaillé'!$Q$2:$Q$244,'Plan détaillé'!$A$2:$A$244,$A8) -> 0 | L8: =IF(J8=0,"",IFERROR(K8/J8-1,"")) -> -1 | M8: =COUNTIFS('Plan détaillé'!$A$2:$A$244,$A8,'Plan détaillé'!$O$2:$O$244,"x") -> 0 | N8: =IFERROR(AVERAGEIFS('Plan détaillé'!$P$2:$P$244,'Plan détaillé'!$A$2:$A$244,$A8,'Plan détaillé'!$P$2:$P$244,">0"),"")
A9: 7 | B9: Construction semi | C9: =SUMIFS('Plan détaillé'!$G$2:$G$244,'Plan détaillé'!$A$2:$A$244,$A9)/60 -> 9.2166667 | D9: =SUMIFS('Plan détaillé'!$G$2:$G$244,'Plan détaillé'!$A$2:$A$244,$A9,'Plan détaillé'!$E$2:$E$244,"Course à pied")/60 -> 3.7166667 | E9: =SUMIFS('Plan détaillé'!$G$2:$G$244,'Plan détaillé'!$A$2:$A$244,$A9,'Plan détaillé'!$E$2:$E$244,"Hyrox")/60 -> 2.75 | F9: =SUMIFS('Plan détaillé'!$G$2:$G$244,'Plan détaillé'!$A$2:$A$244,$A9,'Plan détaillé'!$E$2:$E$244,"Natation")/60 -> 2 | G9: =SUMIFS('Plan détaillé'!$G$2:$G$244,'Plan détaillé'!$A$2:$A$244,$A9,'Plan détaillé'!$E$2:$E$244,"Vélo")/60 -> 0.75 | H9: =SUMIFS('Plan détaillé'!$H$2:$H$244,'Plan détaillé'!$A$2:$A$244,$A9) -> 41.4 | I9: =SUMIFS('Plan détaillé'!$I$2:$I$244,'Plan détaillé'!$A$2:$A$244,$A9) -> 5400 | J9: =SUMIFS('Plan détaillé'!$M$2:$M$244,'Plan détaillé'!$A$2:$A$244,$A9) -> 2975 | K9: =SUMIFS('Plan détaillé'!$Q$2:$Q$244,'Plan détaillé'!$A$2:$A$244,$A9) -> 0 | L9: =IF(J9=0,"",IFERROR(K9/J9-1,"")) -> -1 | M9: =COUNTIFS('Plan détaillé'!$A$2:$A$244,$A9,'Plan détaillé'!$O$2:$O$244,"x") -> 0 | N9: =IFERROR(AVERAGEIFS('Plan détaillé'!$P$2:$P$244,'Plan détaillé'!$A$2:$A$244,$A9,'Plan détaillé'!$P$2:$P$244,">0"),"")
A10: 8 | B10: Construction semi | C10: =SUMIFS('Plan détaillé'!$G$2:$G$244,'Plan détaillé'!$A$2:$A$244,$A10)/60 -> 9.8166667 | D10: =SUMIFS('Plan détaillé'!$G$2:$G$244,'Plan détaillé'!$A$2:$A$244,$A10,'Plan détaillé'!$E$2:$E$244,"Course à pied")/60 -> 3.9833333 | E10: =SUMIFS('Plan détaillé'!$G$2:$G$244,'Plan détaillé'!$A$2:$A$244,$A10,'Plan détaillé'!$E$2:$E$244,"Hyrox")/60 -> 2.75 | F10: =SUMIFS('Plan détaillé'!$G$2:$G$244,'Plan détaillé'!$A$2:$A$244,$A10,'Plan détaillé'!$E$2:$E$244,"Natation")/60 -> 2.3333333 | G10: =SUMIFS('Plan détaillé'!$G$2:$G$244,'Plan détaillé'!$A$2:$A$244,$A10,'Plan détaillé'!$E$2:$E$244,"Vélo")/60 -> 0.75 | H10: =SUMIFS('Plan détaillé'!$H$2:$H$244,'Plan détaillé'!$A$2:$A$244,$A10) -> 44.4 | I10: =SUMIFS('Plan détaillé'!$I$2:$I$244,'Plan détaillé'!$A$2:$A$244,$A10) -> 6400 | J10: =SUMIFS('Plan détaillé'!$M$2:$M$244,'Plan détaillé'!$A$2:$A$244,$A10) -> 3263 | K10: =SUMIFS('Plan détaillé'!$Q$2:$Q$244,'Plan détaillé'!$A$2:$A$244,$A10) -> 0 | L10: =IF(J10=0,"",IFERROR(K10/J10-1,"")) -> -1 | M10: =COUNTIFS('Plan détaillé'!$A$2:$A$244,$A10,'Plan détaillé'!$O$2:$O$244,"x") -> 0 | N10: =IFERROR(AVERAGEIFS('Plan détaillé'!$P$2:$P$244,'Plan détaillé'!$A$2:$A$244,$A10,'Plan détaillé'!$P$2:$P$244,">0"),"")
A11: 9 | B11: Construction semi | C11: =SUMIFS('Plan détaillé'!$G$2:$G$244,'Plan détaillé'!$A$2:$A$244,$A11)/60 -> 10.8 | D11: =SUMIFS('Plan détaillé'!$G$2:$G$244,'Plan détaillé'!$A$2:$A$244,$A11,'Plan détaillé'!$E$2:$E$244,"Course à pied")/60 -> 6.05 | E11: =SUMIFS('Plan détaillé'!$G$2:$G$244,'Plan détaillé'!$A$2:$A$244,$A11,'Plan détaillé'!$E$2:$E$244,"Hyrox")/60 -> 2.25 | F11: =SUMIFS('Plan détaillé'!$G$2:$G$244,'Plan détaillé'!$A$2:$A$244,$A11,'Plan détaillé'!$E$2:$E$244,"Natation")/60 -> 2.5 | G11: =SUMIFS('Plan détaillé'!$G$2:$G$244,'Plan détaillé'!$A$2:$A$244,$A11,'Plan détaillé'!$E$2:$E$244,"Vélo")/60 -> 0 | H11: =SUMIFS('Plan détaillé'!$H$2:$H$244,'Plan détaillé'!$A$2:$A$244,$A11) -> 52.4 | I11: =SUMIFS('Plan détaillé'!$I$2:$I$244,'Plan détaillé'!$A$2:$A$244,$A11) -> 6800 | J11: =SUMIFS('Plan détaillé'!$M$2:$M$244,'Plan détaillé'!$A$2:$A$244,$A11) -> 4154 | K11: =SUMIFS('Plan détaillé'!$Q$2:$Q$244,'Plan détaillé'!$A$2:$A$244,$A11) -> 0 | L11: =IF(J11=0,"",IFERROR(K11/J11-1,"")) -> -1 | M11: =COUNTIFS('Plan détaillé'!$A$2:$A$244,$A11,'Plan détaillé'!$O$2:$O$244,"x") -> 0 | N11: =IFERROR(AVERAGEIFS('Plan détaillé'!$P$2:$P$244,'Plan détaillé'!$A$2:$A$244,$A11,'Plan détaillé'!$P$2:$P$244,">0"),"")
A12: 10 | B12: Construction · allégée | C12: =SUMIFS('Plan détaillé'!$G$2:$G$244,'Plan détaillé'!$A$2:$A$244,$A12)/60 -> 8.1333333 | D12: =SUMIFS('Plan détaillé'!$G$2:$G$244,'Plan détaillé'!$A$2:$A$244,$A12,'Plan détaillé'!$E$2:$E$244,"Course à pied")/60 -> 2.4666667 | E12: =SUMIFS('Plan détaillé'!$G$2:$G$244,'Plan détaillé'!$A$2:$A$244,$A12,'Plan détaillé'!$E$2:$E$244,"Hyrox")/60 -> 2.75 | F12: =SUMIFS('Plan détaillé'!$G$2:$G$244,'Plan détaillé'!$A$2:$A$244,$A12,'Plan détaillé'!$E$2:$E$244,"Natation")/60 -> 2.1666667 | G12: =SUMIFS('Plan détaillé'!$G$2:$G$244,'Plan détaillé'!$A$2:$A$244,$A12,'Plan détaillé'!$E$2:$E$244,"Vélo")/60 -> 0.75 | H12: =SUMIFS('Plan détaillé'!$H$2:$H$244,'Plan détaillé'!$A$2:$A$244,$A12) -> 28.4 | I12: =SUMIFS('Plan détaillé'!$I$2:$I$244,'Plan détaillé'!$A$2:$A$244,$A12) -> 6000 | J12: =SUMIFS('Plan détaillé'!$M$2:$M$244,'Plan détaillé'!$A$2:$A$244,$A12) -> 2666 | K12: =SUMIFS('Plan détaillé'!$Q$2:$Q$244,'Plan détaillé'!$A$2:$A$244,$A12) -> 0 | L12: =IF(J12=0,"",IFERROR(K12/J12-1,"")) -> -1 | M12: =COUNTIFS('Plan détaillé'!$A$2:$A$244,$A12,'Plan détaillé'!$O$2:$O$244,"x") -> 0 | N12: =IFERROR(AVERAGEIFS('Plan détaillé'!$P$2:$P$244,'Plan détaillé'!$A$2:$A$244,$A12,'Plan détaillé'!$P$2:$P$244,">0"),"")
A13: 11 | B13: Construction semi | C13: =SUMIFS('Plan détaillé'!$G$2:$G$244,'Plan détaillé'!$A$2:$A$244,$A13)/60 -> 9.7833333 | D13: =SUMIFS('Plan détaillé'!$G$2:$G$244,'Plan détaillé'!$A$2:$A$244,$A13,'Plan détaillé'!$E$2:$E$244,"Course à pied")/60 -> 3.7 | E13: =SUMIFS('Plan détaillé'!$G$2:$G$244,'Plan détaillé'!$A$2:$A$244,$A13,'Plan détaillé'!$E$2:$E$244,"Hyrox")/60 -> 2.75 | F13: =SUMIFS('Plan détaillé'!$G$2:$G$244,'Plan détaillé'!$A$2:$A$244,$A13,'Plan détaillé'!$E$2:$E$244,"Natation")/60 -> 2.5833333 | G13: =SUMIFS('Plan détaillé'!$G$2:$G$244,'Plan détaillé'!$A$2:$A$244,$A13,'Plan détaillé'!$E$2:$E$244,"Vélo")/60 -> 0.75 | H13: =SUMIFS('Plan détaillé'!$H$2:$H$244,'Plan détaillé'!$A$2:$A$244,$A13) -> 41.4 | I13: =SUMIFS('Plan détaillé'!$I$2:$I$244,'Plan détaillé'!$A$2:$A$244,$A13) -> 7200 | J13: =SUMIFS('Plan détaillé'!$M$2:$M$244,'Plan détaillé'!$A$2:$A$244,$A13) -> 3231 | K13: =SUMIFS('Plan détaillé'!$Q$2:$Q$244,'Plan détaillé'!$A$2:$A$244,$A13) -> 0 | L13: =IF(J13=0,"",IFERROR(K13/J13-1,"")) -> -1 | M13: =COUNTIFS('Plan détaillé'!$A$2:$A$244,$A13,'Plan détaillé'!$O$2:$O$244,"x") -> 0 | N13: =IFERROR(AVERAGEIFS('Plan détaillé'!$P$2:$P$244,'Plan détaillé'!$A$2:$A$244,$A13,'Plan détaillé'!$P$2:$P$244,">0"),"")
... A31: 29 | B31: 10 km n°3 · objectif | C31: =SUMIFS('Plan détaillé'!$G$2:$G$244,'Plan détaillé'!$A$2:$A$244,$A31)/60 -> 5.5666667 | D31: =SUMIFS('Plan détaillé'!$G$2:$G$244,'Plan détaillé'!$A$2:$A$244,$A31,'Plan détaillé'!$E$2:$E$244,"Course à pied")/60 -> 1.5666667 | E31: =SUMIFS('Plan détaillé'!$G$2:$G$244,'Plan détaillé'!$A$2:$A$244,$A31,'Plan détaillé'!$E$2:$E$244,"Hyrox")/60 -> 0.83333333 | F31: =SUMIFS('Plan détaillé'!$G$2:$G$244,'Plan détaillé'!$A$2:$A$244,$A31,'Plan détaillé'!$E$2:$E$244,"Natation")/60 -> 3.1666667 | G31: =SUMIFS('Plan détaillé'!$G$2:$G$244,'Plan détaillé'!$A$2:$A$244,$A31,'Plan détaillé'!$E$2:$E$244,"Vélo")/60 -> 0 | H31: =SUMIFS('Plan détaillé'!$H$2:$H$244,'Plan détaillé'!$A$2:$A$244,$A31) -> 20 | I31: =SUMIFS('Plan détaillé'!$I$2:$I$244,'Plan détaillé'!$A$2:$A$244,$A31) -> 8800 | J31: =SUMIFS('Plan détaillé'!$M$2:$M$244,'Plan détaillé'!$A$2:$A$244,$A31) -> 1765 | K31: =SUMIFS('Plan détaillé'!$Q$2:$Q$244,'Plan détaillé'!$A$2:$A$244,$A31) -> 0 | L31: =IF(J31=0,"",IFERROR(K31/J31-1,"")) -> -1 | M31: =COUNTIFS('Plan détaillé'!$A$2:$A$244,$A31,'Plan détaillé'!$O$2:$O$244,"x") -> 0 | N31: =IFERROR(AVERAGEIFS('Plan détaillé'!$P$2:$P$244,'Plan détaillé'!$A$2:$A$244,$A31,'Plan détaillé'!$P$2:$P$244,">0"),"")
A32: TOTAL | C32: =SUM(C2:C31) -> 261.1 | D32: =SUM(D2:D31) -> 105.91667 | E32: =SUM(E2:E31) -> 61.25 | F32: =SUM(F2:F31) -> 75.416667 | G32: =SUM(G2:G31) -> 18.516667 | H32: =SUM(H2:H31) -> 1115.7 | I32: =SUM(I2:I31) -> 208100 | J32: =SUM(J2:J31) -> 83027 | K32: =SUM(K2:K31) -> 0
A34: Fond orange : les quatre semaines de course (S12 semi, S13 10 km n°1, S24 10 km n°2, S29 10 km n°3) — seules exceptions au plancher de 8h.
A35: Fond vert : semaines allégées (S4, S10, S18, S28).
A36: Le vélo est la variable d'ajustement : 45' minimum, davantage quand les autres disciplines ne remplissent pas les 8h.
A37: Le kilométrage des semaines 12, 13, 24 et 29 inclut la course.

Sheet Suivi & ajustement
A1: SUIVI HEBDOMADAIRE ET RÈGLES D'AJUSTEMENT
A2: Deux séances gouvernent tout le plan : la séance de qualité du mercredi et la sortie longue. Le reste s'adapte autour d'elles. Remplis le tableau chaque dimanche soir — c'est ce qui permet de corriger avant que ça casse.
A4: POINT DE DÉPART MESURÉ — sortie de référence transmise (Garmin)
A5: Mesure | B5: Valeur | C5: Lecture
A6: Allure moyenne | B6: 5:12 /km | C6: Sur ~55 min, soit un 10 km en 52:00. C'est ta référence « allure 10 km actuelle » dans l'onglet Allures.
A7: FC moyenne | B7: 147 bpm | C7: À 5:12/km. Ce n'est pas une allure d'endurance : c'est déjà proche de ton seuil actuel.
A8: FC au repos | B8: 44 bpm (moy. 7 j : 45) | C8: Après douze mois d'arrêt. Ton moteur cardiaque a très peu perdu — c'est la bonne nouvelle, et le piège.
A9: Dérive cardiaque | B9: ≈ 140 → 160 bpm à allure constante | C9: +14 % sur 55 minutes. Au-delà de 5 %, l'allure était trop rapide pour ton état d'endurance actuel.
A10: Condition physique Garmin | B10: positive au départ, négative après 27' | C10: La montre dit que l'effort dépassait la forme du jour à partir de la mi-parcours.
A11: Ce que ça change dans le plan | B11: Rien — ça le confirme | C11: Ton endurance fondamentale est à 6:27/km en bloc A, pas à 5:12. 5:12 est aujourd'hui ton allure de course, pas ton allure de footing.
A13: CE QUE TU M'ENVOIES CHAQUE DIMANCHE SOIR
B14: Quoi | C14: Détail | D14: Exemple
A15: 1 | B15: La séance de qualité du mercredi | C15: Temps réel de chaque bloc, FC moyenne, RPE ressenti, et une phrase de sensation. | D15: Ex : 5 × 3' seuil visés à 5:22 → réalisés 5:19 / 5:20 / 5:22 / 5:26 / 5:31, FC 158-168, RPE 8, les 2 derniers durs.
A16: 2 | B16: La sortie longue | C16: Distance, temps, allure moyenne, FC moyenne, dérive début/fin. | D16: Ex : 12 km en 1h18, 6:30/km, FC 138 → 149.
A17: 3 | B17: L'état général | C17: Sommeil, fatigue, douleurs éventuelles, FC au repos de la semaine. | D17: Ex : 3 nuits courtes, tendon d'Achille gauche sensible mercredi et jeudi, FC repos 47 (vs 44).
A18: 4 | B18: Ce qui a sauté | C18: Les séances non faites et pourquoi. | D18: Ex : vélo du mardi supprimé, réunion tardive.
A20: LES RÈGLES D'AJUSTEMENT — appliquées sans discussion
A21: Si… | B21: Alors | C21: Pourquoi
A22: RPE du mercredi > 8 | B22: Tu ralentis de 10 s/km la séance suivante. | C22: Le RPE cible du fractionné est 7-8. Au-dessus, tu cours l'allure de la semaine 20 en semaine 15.
A23: RPE du mercredi ≤ 6 | B23: Tu peux accélérer de 5 s/km. | C23: Capacité disponible : c'est le seul cas où on avance le curseur plus vite que le plan.
A24: Dérive cardiaque > 8 % sur la sortie longue | B24: Tu ralentis l'endurance de 15 s/km pendant deux semaines. | C24: Signe que la base aérobie ne suit pas encore le volume.
A25: FC au repos +5 bpm sur 3 jours | B25: Semaine allégée immédiate : on coupe le vélo et Hyrox n°2. | C25: Le meilleur indicateur de surcharge que tu aies, et tu l'as déjà au poignet.
A26: Sensation « dur » deux semaines de suite | B26: Décharge anticipée, on avance la semaine allégée suivante. | C26: Ce n'est pas de la faiblesse, c'est le mécanisme du plan.
A27: Douleur tendineuse 2 jours de suite | B27: STOP course 5 jours. Natation et Hyrox haut du corps seulement. | C27: Le volume perdu se rattrape. Une tendinopathie, non — et c'est ton risque n°1.
A28: Deux nuits courtes d'affilée | B28: La séance de qualité devient un footing. | C28: Sans discussion.
A29: Une séance saute | B29: Elle ne se rattrape jamais. On reprend où le plan en est. | C29: Ordre de sacrifice : vélo, puis Hyrox n°2, puis natation du vendredi. Jamais la longue, jamais la qualité.
A31: JOURNAL HEBDOMADAIRE — à remplir
A32: Semaine | B32: Date du dimanche | C32: Séance qualité : temps réels | D32: FC moy. qualité | E32: RPE qualité | F32: Sortie longue : allure moy. | G32: FC repos moyenne | H32: Sensation générale / douleurs / décision
A33: 1 | B33: 6/09/2026 | C33: — | H33: Semaine 1 amputée : déplacement pro du 2 au 5/09, un seul footing.
A34: 2
A35: 3
A36: 4
A37: 5
A38: 6
A39: 7
A40: 8
A41: 9
A42: 10
A43: 11
A44: 12
...

Sheet Allures
A1: CALIBRAGE DES ALLURES — DEUX RÉFÉRENCES, PAS UNE
A2: Tu pars de 52 min au 10 km et tu vises 36 min. Les allures d'entraînement ne peuvent donc pas être fixes : elles glissent bloc par bloc. Renseigne les deux cellules jaunes — allure actuelle et allure cible — et tout le plan se recalcule.
A4: Allure 10 km ACTUELLE — min | B4: 5
A5: Allure 10 km ACTUELLE — sec | B5: 12
A6: Allure 10 km CIBLE — min | B6: 3
A7: Allure 10 km CIBLE — sec | B7: 36
A8: Allure actuelle (sec/km) | B8: =B4*60+B5 -> 312
A9: Allure cible (sec/km) | B9: =B6*60+B7 -> 216
A10: 10 km actuel / cible | B10: =TEXT(B8*10/86400,"[m]:ss")&" → "&TEXT(B9*10/86400,"[m]:ss") -> 52:00 → 36:00
A12: Bloc | B12: Semaines | C12: Allure 10 km de référence | D12: 10 km équivalent | E12: Ce que ça veut dire
A13: A — Réamorçage | B13: S1 → S6 | C13: =$B$8 -> 312 | D13: =TEXT(C13*10/86400,"[m]:ss") -> 52:00 | E13: Ton niveau actuel. Aucune allure imposée avant le test de la semaine 5.
A14: B — Construction semi | B14: S7 → S13 | C14: =$B$8-($B$8-$B$9)*0.28 -> 285.12 | D14: =TEXT(C14*10/86400,"[m]:ss") -> 47:31 | E14: Le semi du 22/11 et le 10 km du 29/11 se courent à cette référence.
A15: C — Bloc vitesse | B15: S14 → S23 | C15: =$B$8-($B$8-$B$9)*0.65 -> 249.6 | D15: =TEXT(C15*10/86400,"[m]:ss") -> 41:36 | E15: Le fractionné du mercredi vise cette allure, pas 3:36.
A16: D — Bloc final | B16: S24 → S29 | C16: =$B$9 -> 216 | D16: =TEXT(C16*10/86400,"[m]:ss") -> 36:00 | E16: La cible. C'est seulement ici que 3:36/km devient l'allure de travail.
A18: Zone | B18: Code dans le plan | C18: Écart vs allure 10 km (sec/km) | D18: Bloc A | E18: Bloc B | F18: Bloc C | G18: Bloc D | H18: Où elle sert
A19: Récupération | B19: Récup | C19: 95 | D19: =TEXT(($C$13+$C$19)/86400,"mm:ss") -> 06:47 | E19: =TEXT(($C$14+$C$19)/86400,"mm:ss") -> 06:20 | F19: =TEXT(($C$15+$C$19)/86400,"mm:ss") -> 05:44 | G19: =TEXT(($C$16+$C$19)/86400,"mm:ss") -> 05:11 | H19: Footings de récupération du vendredi, retours au calme
A20: Endurance fondamentale | B20: EF | C20: 75 | D20: =TEXT(($C$13+$C$20)/86400,"mm:ss") -> 06:27 | E20: =TEXT(($C$14+$C$20)/86400,"mm:ss") -> 06:00 | F20: =TEXT(($C$15+$C$20)/86400,"mm:ss") -> 05:24 | G20: =TEXT(($C$16+$C$20)/86400,"mm:ss") -> 04:51 | H20: Sorties longues, footings, base du volume
A21: Endurance active | B21: End. active | C21: 55 | D21: =TEXT(($C$13+$C$21)/86400,"mm:ss") -> 06:07 | E21: =TEXT(($C$14+$C$21)/86400,"mm:ss") -> 05:40 | F21: =TEXT(($C$15+$C$21)/86400,"mm:ss") -> 05:04 | G21: =TEXT(($C$16+$C$21)/86400,"mm:ss") -> 04:31 | H21: Blocs en fin de sortie longue, phase de réamorçage
A22: Allure marathon | B22: All. marathon | C22: 30 | D22: =TEXT(($C$13+$C$22)/86400,"mm:ss") -> 05:42 | E22: =TEXT(($C$14+$C$22)/86400,"mm:ss") -> 05:15 | F22: =TEXT(($C$15+$C$22)/86400,"mm:ss") -> 04:39 | G22: =TEXT(($C$16+$C$22)/86400,"mm:ss") -> 04:06 | H22: Blocs sur les sorties longues du bloc vitesse
A23: Allure semi | B23: All. semi | C23: 14 | D23: =TEXT(($C$13+$C$23)/86400,"mm:ss") -> 05:26 | E23: =TEXT(($C$14+$C$23)/86400,"mm:ss") -> 04:59 | F23: =TEXT(($C$15+$C$23)/86400,"mm:ss") -> 04:23 | G23: =TEXT(($C$16+$C$23)/86400,"mm:ss") -> 03:50 | H23: Blocs spécifiques S9 à S12, semi du 22/11
A24: Seuil | B24: Seuil | C24: 10 | D24: =TEXT(($C$13+$C$24)/86400,"mm:ss") -> 05:22 | E24: =TEXT(($C$14+$C$24)/86400,"mm:ss") -> 04:55 | F24: =TEXT(($C$15+$C$24)/86400,"mm:ss") -> 04:19 | G24: =TEXT(($C$16+$C$24)/86400,"mm:ss") -> 03:46 | H24: Séances de seuil : 3', 8', 10', 15'
A25: Allure 10 km — RÉFÉRENCE | B25: All. 10 km | C25: 0 | D25: =TEXT(($C$13+$C$25)/86400,"mm:ss") -> 05:12 | E25: =TEXT(($C$14+$C$25)/86400,"mm:ss") -> 04:45 | F25: =TEXT(($C$15+$C$25)/86400,"mm:ss") -> 04:09 | G25: =TEXT(($C$16+$C$25)/86400,"mm:ss") -> 03:36 | H25: Fractionné du mercredi, et les quatre courses
A26: Allure 5 km / VMA | B26: All. 5 km / VMA | C26: -10 | D26: =TEXT(($C$13+$C$26)/86400,"mm:ss") -> 05:02 | E26: =TEXT(($C$14+$C$26)/86400,"mm:ss") -> 04:35 | F26: =TEXT(($C$15+$C$26)/86400,"mm:ss") -> 03:59 | G26: =TEXT(($C$16+$C$26)/86400,"mm:ss") -> 03:26 | H26: 5 × 1000 m, 10 × 800 m, 12 × 400 m
A28: La colonne « Allures cibles » de l'onglet Plan détaillé utilise automatiquement le bloc correspondant à la semaine de la séance.
A29: Le contre-la-montre de 30' en semaine 5 remplace l'estimation : reporte le résultat dans la cellule « allure actuelle » et tout se recale.
A30: Correction : les allures d'endurance de ton fichier d'origine (6:30-7:00/km) étaient cohérentes avec ton niveau actuel — c'est moi qui les avais jugées fausses en les comparant à la cible de mars. Elles décrivaient le début du plan, pas la fin.
A31: Cellules jaunes = à remplir. Tout le reste se recalcule.

Sheet Courses montagne
A1: LA SÉRIE MONTAGNE — UNE SORTIE TOUTES LES 3 SEMAINES
A2: Cinq sorties, +2 à +5 km à chaque fois, de 16 km le 29 août à 41 km le 12 décembre. L'occurrence du 21/11 a été supprimée : elle tombait la veille du semi. Et la première passe de 25 à 16 km : après douze mois d'arrêt, le 25 km coûterait trois semaines de reprise. Courses recherchées dans un rayon de deux heures de route autour de Wrocław, sur le calendrier biegigorskie.pl et les calendriers dolnośląskie.
A4: Sortie | B4: Date | C4: Distance cible | D4: Course identifiée | E4: Lieu | F4: Trajet depuis Wrocław | G4: Remarque
A5: 1 | B5: Samedi 29/08/2026 | C5: 16 km (au lieu de 25) | D5: Bieg Jaskiniowego Niedźwiedzia | E5: Kletno, Masyw Śnieżnika | F5: ≈ 130 km de Wrocław, 2h de route | G5: Le 25 km existe, mais après douze mois d'arrêt c'est le 16 km qu'il faut prendre — même course, même jour, même lieu. Le 25 km te coûterait trois semaines de reprise pour rien. Formats disponibles : 10, 16, 25 et 51 km.
D6: https://bjn.com.pl/25km/
A7: 2 | B7: Samedi 19/09/2026 | C7: 30 km | D7: Przejście Nocna 30 — 30 km | E7: Départ Piechowice, arrivée Szklarska Poręba | F7: ≈ 130 km de Wrocław | G7: 30 km en montagne à la troisième semaine de reprise après douze mois d'arrêt. C'est trois fois ta plus longue sortie de la semaine précédente. Si tu maintiens, marche dès 8 % de pente et vise la barrière, pas le chrono.
D8: https://przejsciekotliny.org/
A9: 3 | B9: Dimanche 11/10/2026 | C9: 35 km | D9: UltraKotlina UK30 — 35 km | E9: Départ Piechowice, Karkonosze et Góry Izerskie | F9: ≈ 130 km de Wrocław | G9: Départ le dimanche : la sortie se décale d'un jour, le samedi devient repos et route. Barrière 6h.
D10: https://ultrakotlina.pl/
A11: 4 | B11: Samedi 31/10/2026 | C11: 37 km | D11: Sowiogórski Festiwal Biegowy — 30 km | E11: Pieszyce, Góry Sowie | F11: ≈ 70 km de Wrocław, 1h10 — la plus proche de la série | G11: Rien le 31/10 à moins de deux heures. Celle-ci est une semaine plus tôt et fait 30 km au lieu de 37. Le festival propose aussi 55 et 84 km. À ce stade du plan, prendre le 30 km une semaine avant est le meilleur des compromis : tu gardes une vraie course, tu perds seulement la progression en distance.
D12: https://b4sportonline.pl/sfb2026/
A13: 5 | B13: Samedi 12/12/2026 | C13: 41 km | D13: Winter Trail Małopolska — 45 km | E13: Mszana Dolna, Beskid Wyspowy | F13: ≈ 370 km de Wrocław, 4h30 de route | G13: Seule course qui tombe à ta date et à ta distance, mais à 4h30 de route. Et surtout : le 12/12 tombe désormais en pleine préparation du 10 km. Une sortie de 41 km en montagne au milieu d'un bloc de vitesse, c'est deux entraînements qui s'annulent. Mon avis : tu supprimes cette cinquième sortie, ou tu acceptes que le 10 km de février soit décalé.
D14: https://motivato.pl/kalendarz-biegowy/biegi-gorskie/
A16: Les deux dernières sorties (31/10 et 12/12) n'ont aucune course correspondante à moins de deux heures de Wrocław : elles se font en solo.
A17: Sur la sortie du 11/10, le départ est un dimanche : la sortie se décale d'un jour et le samedi 10 devient repos et route.
A18: Vérifie les dates et les ouvertures d'inscription sur les sites officiels : les calendriers agrégés se trompent régulièrement d'un jour.
A19: Sources : biegigorskie.pl, przejsciekotliny.org, ultrakotlina.pl, bjn.com.pl, ultrarace.pl, finishers.com, running.life.

Sheet Exercices Hyrox
A1: LES EXERCICES HYROX, UN PAR UN
A2: Format officiel : 8 × 1 km de course, entrecoupés des 8 stations ci-dessous, dans cet ordre. Environ 16 km au total. Poids indiqués pour la division Open hommes, saison 2026 — vérifie ceux de ta division sur hyrox.com.
A4: LES 8 STATIONS, DANS L'ORDRE DE LA COURSE
A5: # | B5: Station | C5: Standard (Open H) | D5: Autres divisions | E5: Ce que c'est | F5: Les 3 points de technique qui comptent | G5: L'erreur classique | H5: Repère de temps | I5: Où elle apparaît dans le plan
A6: 1 | B6: SkiErg — 1 000 m | C6: 1 000 m, sans charge | D6: Identique en Pro et en Open, hommes et femmes | E6: Machine de ski de fond : tirage vertical debout, à la corde. Premier effort de la course, juste après le premier kilomètre. | F6: 1) L'impulsion vient des hanches et du gainage, pas des bras — tu t'assieds sur la poignée. 2) Mains qui descendent le long du corps, coudes près du buste. 3) Coups longs plutôt que fréquence haute : 24 à 28 coups/min. | G6: Tirer à la force des bras. Tu explores tes avant-bras dès la station 1, et tu paies l'addition sur le sled pull et le farmers 40 minutes plus tard. | H6: 4'00 à 4'45 (Open) | I6: Séries de 250 à 500 m dans chaque Hyrox n°1 du lundi, et en station dans les circuits du jeudi.
A7: 2 | B7: Sled Push — 50 m | C7: 152 kg, traîneau compris (Open H) | D7: Pro H 202 kg · Open F 102 kg | E7: Pousser un traîneau lesté sur 50 m, en 4 allers de 12,5 m. La station qui fait exploser le plus de courses. | F7: 1) Bras tendus et verrouillés, corps en ligne à environ 45°. 2) Pas courts et fréquents — on ne cherche jamais la longueur de pas. 3) Hanches basses, regard au sol quelques mètres devant. | G7: Bras fléchis : tu portes le traîneau au lieu de le pousser. Et des pauses de 20 secondes à chaque demi-tour, qui coûtent plus que la poussée elle-même. | H7: 2'30 à 4'00 (Open) | I7: Introduit à vide en semaine 3 (technique seulement), chargé à partir de la semaine 4 : 4 à 6 × 15 m le lundi.
A8: 3 | B8: Sled Pull — 50 m | C8: 103 kg, traîneau compris (Open H) | D8: Pro H 153 kg · Open F 78 kg | E8: Tirer le traîneau à la corde jusqu'à soi, depuis une zone délimitée dont tu ne dois pas sortir. | F8: 1) Hanches basses, dos plat : tu tires avec les jambes en reculant, pas avec les bras. 2) Mains alternées, main sur main, sans jamais lâcher la corde. 3) Range la corde proprement à chaque aller — un nœud coûte 30 secondes. | G8: Tirer debout, bras tendus, dos rond. Lombaires cuites pour le reste de la course, et c'est encore la station 3 sur 8. | H8: 3'30 à 5'00 (Open) | I8: À partir de la semaine 4 : 4 à 6 × 15 m le lundi, en alternance avec le sled push.
A9: 4 | B9: Burpee Broad Jumps — 80 m | C9: 80 m, poids du corps | D9: Identique dans toutes les divisions | E9: Enchaînement burpee + saut à pieds joints vers l'avant, sur 80 m. La station la plus coûteuse cardiaquement. | F9: 1) Poitrine au sol, puis saut vers l'avant à deux pieds (les deux sont des standards de validation). 2) Économise : burpee bas, saut court et régulier plutôt que long et explosif. 3) Respire au moment du saut, jamais au sol. | G9: Partir sur des sauts maximaux. Ta fréquence cardiaque plafonne au bout de 20 m et les 60 m restants deviennent un calvaire. | H9: 3'30 à 5'30 (Open) | I9: 10 à 15 répétitions par tour dans les circuits du jeudi, surtout en semaines 1 à 3.
A10: 5 | B10: RowErg — 1 000 m | C10: 1 000 m, sans charge | D10: Identique en Pro et en Open | E10: Rameur Concept2, 1 000 m. Station 5, à peu près à la moitié de la course. | F10: 1) Séquence stricte : jambes → tronc → bras à la traction, bras → tronc → jambes au retour. 2) Cadence 24 à 28, ratio traction/retour d'environ 1:2. 3) Amortisseur réglé entre 4 et 6, jamais 10. | G10: Partir à 1'45/500 m parce que la machine le permet, puis s'effondrer. Et se relever d'un coup à la fin : vertige garanti avant le kilomètre suivant. | H10: 3'45 à 4'30 (Open) | I10: Séries de 250 à 500 m le lundi, et en station dans les circuits du jeudi.
A11: 6 | B11: Farmers Carry — 200 m | C11: 2 × 24 kg (Open H) | D11: Pro H 2 × 32 kg · Open F 2 × 16 kg | E11: Porter deux kettlebells sur 200 m. Station la plus rapide, mais celle qui décide de ce qu'il te reste dans les mains. | F11: 1) Épaules basses et en arrière, gainage serré, buste droit. 2) Petits pas rapides — on trottine, on ne marche pas. 3) Si tu dois lâcher, pose les poids à plat et repars immédiatement. | G11: Ne jamais avoir travaillé la prise de main. Les jambes suivent parfaitement, mais les doigts lâchent à 120 m. | H11: 1'45 à 2'30 (Open), idéalement en une ou deux prises | I11: 3 à 5 × 30 à 50 m à chaque Hyrox n°1, charge progressive de la semaine 1 à la semaine 10.
A12: 7 | B12: Sandbag Lunges — 100 m | C12: 20 kg (Open H) | D12: Pro H 30 kg · Open F 10 kg | E12: Fentes marchées avec un sac de sable sur les épaules, sur 100 m. La station où arrivent les crampes. | F12: 1) Sac haut sur les trapèzes, jamais sur la nuque. 2) Genou arrière qui touche le sol à chaque fente — c'est le standard de validation. 3) Pas courts, buste droit : on ne tombe pas vers l'avant. | G12: Des fentes trop longues. Les quadriceps crampent vers 60 m, et un genou qui ne touche pas, c'est un no-rep. | H12: 4'00 à 6'00 (Open) | I12: 20 m de fentes lestées dans les circuits du jeudi ; les fentes bulgares du lundi construisent la force unilatérale correspondante.
A13: 8 | B13: Wall Balls — 100 répétitions | C13: 6 kg, cible à 3,00 m (Open H) | D13: Pro H 9 kg · Open F 4 kg à 2,70 m | E13: Squat complet puis lancer de la balle lestée sur une cible en hauteur, 100 fois. Dernière station de la course. | F13: 1) Squat complet, hanches sous le parallèle : la balle part des jambes, pas des épaules. 2) Réception bras déjà en position, on enchaîne sans temps mort. 3) Fractionne dès le début — 10 × 10 ou 5-4-3 — plutôt que d'aller à l'échec. | G13: Enchaîner 30 répétitions d'entrée. Tu finis par séries de 3, avec des no-reps parce que la hanche ne descend plus. | H13: 5'00 à 8'00 (Open) | I13: 15 à 25 répétitions par tour dans les circuits, jusqu'à 5 × 25 en semaine 10.
A15: LES DEUX FACTEURS QU'ON OUBLIE
A16: # | B16: Station | C16: Standard (Open H) | D16: Autres divisions | E16: Ce que c'est | F16: Les 3 points de technique qui comptent | G16: L'erreur classique | H16: Repère de temps | I16: Où elle apparaît dans le plan
B17: La course entre les stations | C17: 8 × 1 km, soit 8 km au total | E17: Le vrai facteur limitant d'un Hyrox. Ce n'est pas la force qui décide du chrono, c'est la capacité à courir correctement avec des jambes déjà chargées. | F17: 1) Ne cherche jamais à gagner du temps sur les deux premiers kilomètres. 2) Allure cible : ton allure semi + 20 à 30 s/km. 3) Reprends la course immédiatement en sortant de la station, même lentement. | G17: Courir les premiers kilomètres à l'allure dont tu es capable frais. Tu la paies au double à partir de la station 5. | H17: — | I17: C'est exactement l'objet de la séance Hyrox n°2 du jeudi : 400 m de course + 1 station, en boucle.
B18: La Roxzone | C18: Temps de transition entre la fin d'une station et le kilomètre suivant | E18: Les 8 transitions cumulées. Un temps qui n'apparaît nulle part à l'entraînement et qui pèse lourd sur le chrono final. | F18: 1) Sache où est la sortie de station avant d'y entrer. 2) Bois et respire en marchant vite, pas à l'arrêt. 3) Fixe-toi une limite de 45 secondes par transition. | G18: Récupérer debout, mains sur les genoux. Un athlète moyen y perd 6 à 10 minutes sur la course entière. | H18: 6 à 10 min cumulées | I18: Chronomètre tes transitions dans les circuits du jeudi à partir de la semaine 9.
A20: LA MUSCULATION DE SOUTIEN — dans le plan, pas dans la course
A21: Exercice | B21: Volume dans le plan | C21: À quoi ça sert exactement | D21: Quand
A22: Back squat / Goblet squat | B22: 4 × 5 à 8 | C22: Force maximale des jambes. C'est la base du sled push et ce qui te permet de faire 100 wall balls sans que la hanche remonte. | D22: Lundi, tout le plan
A23: Soulevé de terre roumain (RDL) | B23: 3 à 4 × 8 | C23: Chaîne postérieure : ischios et fessiers. Protège les ischios sur les sorties longues et alimente le sled pull. | D23: Lundi, tout le plan
A24: Fentes bulgares | B24: 3 × 10 à 12 par jambe | C24: Force unilatérale. Transfert direct sur les sandbag lunges et sur la stabilité de la foulée en fin de semi. | D24: Lundi, S3 → S28
A25: Hip thrust | B25: 3 × 12 | C25: Extension de hanche pure. Renforce les fessiers sans charger la colonne — utile en phase de réamorçage. | D25: Lundi, S1 → S2
A26: Développé militaire | B26: 3 à 4 × 8 à 10 | C26: Épaules et verrouillage haut. Soutient le ski erg et la fin des wall balls. | D26: Lundi, S2 → S11
A27: Tractions / tirage vertical | B27: 4 × 8 | C27: Dos et grip. Indispensable au sled pull et au ski erg. | D27: Lundi, S1 → S11
A28: Farmer's carry (en musculation) | B28: 3 à 5 × 30 à 50 m | C28: Prise de main et gainage. Transfert 1 pour 1 avec la station de course. | D28: Lundi, toutes les semaines
A29: Gainage | B29: 10 à 12' par séance | C29: Le tronc est ce qui transmet la force au traîneau et ce qui tient la foulée quand tu fatigues. | D29: Lundi et mardi, toutes les semaines
A31: Source des standards : hyrox.com et récapitulatifs de division 2026. Les poids Open peuvent évoluer d'une saison à l'autre — vérifie avant de caler tes charges de sled.
